Workbook

Sheet ARP detection method
B1: ARP detection | I1: 0 = niks gedetecteerd
A2: Staat in nano seconde | I2: 1 = well gedetecteerd
A3: Speed | B3: test 1 | C3: test 2 | D3: test 3 | E3: test 4 | F3: test 5 | G3: gemiddelden | I3: accurasy | J3: test 1 | K3: test 2 | L3: test 3 | M3: test 4 | N3: test 5 | O3: totaal
A4: 1 | B4: 2019238100 | C4: 2014258400 | D4: 2019185600 | E4: 2022443600 | F4: 2023907600 | G4: =SUM(B4:F4)/5 -> 2019806660 | I4: 1 | J4: 1 | K4: 1 | L4: 1 | M4: 1 | N4: 1 | O4: =(SUM(J4:N4)/5) -> 1
A5: 2 | B5: 2024238800 | C5: 2014016200 | D5: 2013852400 | E5: 2023007600 | F5: 2024759100 | G5: =SUM(B5:F5)/5 -> 2019974820 | I5: 2 | J5: 1 | K5: 1 | L5: 1 | M5: 1 | N5: 1 | O5: =(SUM(J5:N5)/5) -> 1
A6: 3 | B6: 2016422600 | C6: 2021191900 | D6: 2011810500 | E6: 2016257900 | F6: 2009458700 | G6: =SUM(B6:F6)/5 -> 2015028320 | I6: 3 | J6: 1 | K6: 1 | L6: 1 | M6: 1 | N6: 1 | O6: =(SUM(J6:N6)/5) -> 1
A7: 4 | B7: 2020148700 | C7: 2020677700 | D7: 2009700600 | E7: 2016247700 | F7: 2014563900 | G7: =SUM(B7:F7)/5 -> 2016267720 | I7: 4 | J7: 1 | K7: 1 | L7: 1 | M7: 1 | N7: 1 | O7: =(SUM(J7:N7)/5) -> 1
A8: 5 | B8: 2063769400 | C8: 2019699000 | D8: 2017097400 | E8: 2018330600 | F8: 2015523500 | G8: =SUM(B8:F8)/5 -> 2026883980 | I8: 5 | J8: 1 | K8: 1 | L8: 1 | M8: 1 | N8: 1 | O8: =(SUM(J8:N8)/5) -> 1
A9: 6 | B9: 2014696000 | C9: 2020294700 | D9: 2017165200 | E9: 2025098400 | F9: 2011880100 | G9: =SUM(B9:F9)/5 -> 2017826880 | I9: 6 | J9: 1 | K9: 1 | L9: 1 | M9: 1 | N9: 1 | O9: =(SUM(J9:N9)/5) -> 1
A10: 7 | B10: 2016141500 | C10: 2014870200 | D10: 2022187000 | E10: 2014510300 | F10: 2026670100 | G10: =SUM(B10:F10)/5 -> 2018875820 | I10: 7 | J10: 1 | K10: 1 | L10: 1 | M10: 1 | N10: 1 | O10: =(SUM(J10:N10)/5) -> 1
A11: 8 | B11: 2013453400 | C11: 2016646700 | D11: 2015751600 | E11: 2010021100 | F11: 2023848200 | G11: =SUM(B11:F11)/5 -> 2015944200 | I11: 8 | J11: 1 | K11: 1 | L11: 1 | M11: 1 | N11: 1 | O11: =(SUM(J11:N11)/5) -> 1
A12: 9 | B12: 2014569600 | C12: 2009278400 | D12: 2012270500 | E12: 2011688900 | F12: 2023596100 | G12: =SUM(B12:F12)/5 -> 2014280700 | I12: 9 | J12: 1 | K12: 1 | L12: 1 | M12: 1 | N12: 1 | O12: =(SUM(J12:N12)/5) -> 1
A13: 10 | B13: 2072294100 | C13: 2006647700 | D13: 2019438500 | E13: 2018237400 | F13: 2012863400 | G13: =SUM(B13:F13)/5 -> 2025896220 | I13: 10 | J13: 1 | K13: 1 | L13: 1 | M13: 1 | N13: 1 | O13: =(SUM(J13:N13)/5) -> 1
A14: 11 | B14: 2012596600 | C14: 2023249700 | D14: 2018118700 | E14: 2009505800 | F14: 2020835200 | G14: =SUM(B14:F14)/5 -> 2016861200 | I14: 11 | J14: 1 | K14: 1 | L14: 1 | M14: 1 | N14: 1 | O14: =(SUM(J14:N14)/5) -> 1
A15: 12 | B15: 2015221500 | C15: 2011143600 | D15: 2011675900 | E15: 2018169600 | F15: 2024272200 | G15: =SUM(B15:F15)/5 -> 2016096560 | I15: 12 | J15: 1 | K15: 1 | L15: 1 | M15: 1 | N15: 1 | O15: =(SUM(J15:N15)/5) -> 1
... A23: 20 | B23: 2004195100 | C23: 2006429200 | D23: 2017566500 | E23: 2015592300 | F23: 2023962500 | G23: =SUM(B23:F23)/5 -> 2013549120 | I23: 20 | J23: 1 | K23: 1 | L23: 1 | M23: 1 | N23: 1 | O23: =(SUM(J23:N23)/5) -> 1
A24: gemiddelden | B24: =MEDIAN(B4:B23) -> 2014632800 | C24: =MEDIAN(C4:C23) -> 2014137300 | D24: =MEDIAN(D4:D23) -> 2016250250 | E24: =MEDIAN(E4:E23) -> 2016252800 | F24: =MEDIAN(F4:F23) -> 2019138950 | G24: =SUM(B24:F24)/5 -> 2016082420 | I24: totaal | J24: =AVERAGE(J4:J23) -> 1 | K24: =AVERAGE(K4:K23) -> 1 | L24: =AVERAGE(L4:L23) -> 1 | M24: =AVERAGE(M4:M23) -> 1 | N24: =AVERAGE(N4:N23) -> 1 | O24: =SUM(J24:N24)/5 -> 1
A27: 0 = niks gedetecteerd
A28: 1 = well gedetecteerd
A29: False postives | B29: test 1 | C29: test 2 | D29: test 3 | E29: test 4 | F29: test 5 | G29: gemiddelden
A30: 1 | B30: 0 | C30: 0 | D30: 0 | E30: 0 | F30: 0 | G30: =(SUM(B30:F30)/5)*100 -> 0
A31: 2 | B31: 0 | C31: 0 | D31: 0 | E31: 0 | F31: 0 | G31: =(SUM(B31:F31)/5)*100 -> 0
A32: 3 | B32: 0 | C32: 0 | D32: 0 | E32: 0 | F32: 0 | G32: =(SUM(B32:F32)/5)*100 -> 0
A33: 4 | B33: 0 | C33: 0 | D33: 0 | E33: 0 | F33: 0 | G33: =(SUM(B33:F33)/5)*100 -> 0
A34: 5 | B34: 0 | C34: 0 | D34: 0 | E34: 0 | F34: 0 | G34: =(SUM(B34:F34)/5)*100 -> 0
A35: 6 | B35: 0 | C35: 0 | D35: 0 | E35: 0 | F35: 0 | G35: =(SUM(B35:F35)/5)*100 -> 0
A36: 7 | B36: 0 | C36: 0 | D36: 0 | E36: 0 | F36: 0 | G36: =(SUM(B36:F36)/5)*100 -> 0
A37: 8 | B37: 0 | C37: 0 | D37: 0 | E37: 0 | F37: 0 | G37: =(SUM(B37:F37)/5)*100 -> 0
A38: 9 | B38: 0 | C38: 0 | D38: 0 | E38: 0 | F38: 0 | G38: =(SUM(B38:F38)/5)*100 -> 0
A39: 10 | B39: 0 | C39: 0 | D39: 0 | E39: 0 | F39: 0 | G39: =(SUM(B39:F39)/5)*100 -> 0
A40: 11 | B40: 0 | C40: 0 | D40: 0 | E40: 0 | F40: 0 | G40: =(SUM(B40:F40)/5)*100 -> 0
A41: 12 | B41: 0 | C41: 0 | D41: 0 | E41: 0 | F41: 0 | G41: =(SUM(B41:F41)/5)*100 -> 0
... A49: 20 | B49: 0 | C49: 0 | D49: 0 | E49: 0 | F49: 0 | G49: =(SUM(B49:F49)/5)*100 -> 0
A50: gemiddelden | B50: =AVERAGE(B30:B49) -> 0 | C50: =AVERAGE(C30:C49) -> 0 | D50: =AVERAGE(D30:D49) -> 0 | E50: =AVERAGE(E30:E49) -> 0 | F50: =AVERAGE(F30:F49) -> 0 | G50: =SUM(B50:F50)/5 -> 0

Sheet Laytency detection method
B1: laytency detection | I1: 0 = niks gedetecteerd
A2: Staat in nano seconde | I2: 1 = well gedetecteerd | K2: staat in milliseconde
A3: Speed | B3: test 1 | C3: test 2 | D3: test 3 | E3: test 4 | F3: test 5 | G3: gemiddelden | I3: laytency MITM | J3: test 1 | K3: test 2 | L3: test 3 | M3: test 4 | N3: test 5 | O3: totaal | Q3: laytency drempel
A4: 1 | B4: 151043700 | C4: 174117300 | D4: 229439600 | E4: 130702200 | F4: 151270000 | G4: =SUM(B4:F4)/5 -> 167314560 | I4: 1 | J4: 13 | K4: 14 | L4: 13.8 | M4: 9.8 | N4: 10.8 | O4: =SUM(J4:N4)/5 -> 12.28 | Q4: 10
A5: 2 | B5: 135969700 | C5: 159895100 | D5: 147354200 | E5: 131800700 | F5: 174394800 | G5: =SUM(B5:F5)/5 -> 149882900 | I5: 2 | J5: 12 | K5: 14.8 | L5: 12.8 | M5: 12.2 | N5: 13.6 | O5: =SUM(J5:N5)/5 -> 13.08
A6: 3 | B6: 137156900 | C6: 139901000 | D6: 129692300 | E6: 121822700 | F6: 167999600 | G6: =SUM(B6:F6)/5 -> 139314500 | I6: 3 | J6: 12.6 | K6: 12.2 | L6: 10.8 | M6: 9.2 | N6: 12.2 | O6: =SUM(J6:N6)/5 -> 11.4
A7: 4 | B7: 152060300 | C7: 150347100 | D7: 119678100 | E7: 140309100 | F7: 168204300 | G7: =SUM(B7:F7)/5 -> 146119780 | I7: 4 | J7: 14.2 | K7: 13.6 | L7: 9.4 | M7: 12 | N7: 15.2 | O7: =SUM(J7:N7)/5 -> 12.88
A8: 5 | B8: 138096000 | C8: 154779300 | D8: 155759600 | E8: 215989800 | F8: 170526100 | G8: =SUM(B8:F8)/5 -> 167030160 | I8: 5 | J8: 13.4 | K8: 13.8 | L8: 15.2 | M8: 14.4 | N8: 16.2 | O8: =SUM(J8:N8)/5 -> 14.6
A9: 6 | B9: 128768300 | C9: 128070000 | D9: 139796300 | E9: 138948500 | F9: 159896500 | G9: =SUM(B9:F9)/5 -> 139095920 | I9: 6 | J9: 12 | K9: 11 | L9: 12.8 | M9: 11.6 | N9: 14.8 | O9: =SUM(J9:N9)/5 -> 12.44
A10: 7 | B10: 122602200 | C10: 155227700 | D10: 151140700 | E10: 120078900 | F10: 132655800 | G10: =SUM(B10:F10)/5 -> 136341060 | I10: 7 | J10: 10.2 | K10: 14.4 | L10: 14.4 | M10: 10.2 | N10: 10.6 | O10: =SUM(J10:N10)/5 -> 11.96
A11: 8 | B11: 136207600 | C11: 152106100 | D11: 131576800 | E11: 137137400 | F11: 178900000 | G11: =SUM(B11:F11)/5 -> 147185580 | I11: 8 | J11: 12.8 | K11: 12.8 | L11: 11 | M11: 12 | N11: 14.6 | O11: =SUM(J11:N11)/5 -> 12.64
A12: 9 | B12: 221377200 | C12: 239240700 | D12: 124596600 | E12: 140016000 | F12: 159811500 | G12: =SUM(B12:F12)/5 -> 177008400 | I12: 9 | J12: 29.6 | K12: 11.6 | L12: 10.6 | M12: 13.2 | N12: 13.6 | O12: =SUM(J12:N12)/5 -> 15.72
A13: 10 | B13: 160434400 | C13: 245971300 | D13: 482259000 | E13: 131550100 | F13: 196098300 | G13: =SUM(B13:F13)/5 -> 243262620 | I13: 10 | J13: 17.4 | K13: 11.8 | L13: 13.6 | M13: 10.6 | N13: 14.8 | O13: =SUM(J13:N13)/5 -> 13.64
A14: 11 | B14: 134747300 | C14: 158349200 | D14: 146766500 | E14: 149546800 | F14: 151123100 | G14: =SUM(B14:F14)/5 -> 148106580 | I14: 11 | J14: 12.8 | K14: 14.4 | L14: 13.8 | M14: 13 | N14: 13.8 | O14: =SUM(J14:N14)/5 -> 13.56
A15: 12 | B15: 135202900 | C15: 148268400 | D15: 120380100 | E15: 120870300 | F15: 140841900 | G15: =SUM(B15:F15)/5 -> 133112720 | I15: 12 | J15: 13.4 | K15: 13.8 | L15: 9 | M15: 9.8 | N15: 12.2 | O15: =SUM(J15:N15)/5 -> 11.64
A16: 13 | B16: 150574500 | C16: 164295200 | D16: 156243700 | E16: 120527500 | F16: 159285700 | G16: =SUM(B16:F16)/5 -> 150185320 | I16: 13 | J16: 15 | K16: 15.4 | L16: 15 | M16: 9.6 | N16: 13.6 | O16: =SUM(J16:N16)/5 -> 13.72
... A23: 20 | B23: 133610400 | C23: 181211700 | D23: 136932400 | E23: 121448400 | F23: 182316400 | G23: =SUM(B23:F23)/5 -> 151103860 | I23: 20 | J23: 12 | K23: 18 | L23: 11.4 | M23: 9.6 | N23: 15 | O23: =SUM(J23:N23)/5 -> 13.2
A24: gemiddelden | B24: =SUM(B4:B23)/20 -> 144996450 | C24: =SUM(C4:C23)/20 -> 167338810 | D24: =SUM(D4:D23)/20 -> 158910505 | E24: =SUM(E4:E23)/20 -> 136369300 | F24: =SUM(F4:F23)/20 -> 168217180 | G24: =SUM(B24:F24)/5 -> 155166449 | I24: totaal | J24: =SUM(J4:J23)/20 -> 14.15 | K24: =SUM(K4:K23)/20 -> 14.13 | L24: =SUM(L4:L23)/20 -> 12.24 | M24: =SUM(M4:M23)/20 -> 11.36 | N24: =SUM(N4:N23)/20 -> 13.98 | O24: =SUM(J24:N24)/5 -> 13.172
A31: 0 = niks gedetecteerd | I31: 0 = niks gedetecteerd
A32: 1 = well gedetecteerd | I32: 1 = well gedetecteerd
A33: laytency no MITM | B33: test 1 | C33: test 2 | D33: test 3 | E33: test 4 | F33: test 5 | G33: gemiddelden | I33: accurasy | J33: test 1 | K33: test 2 | L33: test 3 | M33: test 4 | N33: test 5 | O33: totaal
A34: 1 | B34: 1 | C34: 1 | D34: 1 | E34: 1 | F34: 1 | G34: =SUM(B34:F34)/5 -> 1 | I34: 1 | J34: =IF(J4>$Q$4,1,0) -> 1 | K34: =IF(K4>$Q$4,1,0) -> 1 | L34: =IF(L4>$Q$4,1,0) -> 1 | M34: =IF(M4>$Q$4,1,0) -> 0 | N34: =IF(N4>$Q$4,1,0) -> 1 | O34: =AVERAGE(J34:N34) -> 0.8
A35: 2 | B35: 1 | C35: 1 | D35: 1 | E35: 1 | F35: 1 | G35: =SUM(B35:F35)/5 -> 1 | I35: 2 | J35: =IF(J5>$Q$4,1,0) -> 1 | K35: =IF(K5>$Q$4,1,0) -> 1 | L35: =IF(L5>$Q$4,1,0) -> 1 | M35: =IF(M5>$Q$4,1,0) -> 1 | N35: =IF(N5>$Q$4,1,0) -> 1 | O35: =AVERAGE(J35:N35) -> 1
A36: 3 | B36: 1 | C36: 1 | D36: 1 | E36: 1 | F36: 1 | G36: =SUM(B36:F36)/5 -> 1 | I36: 3 | J36: =IF(J6>$Q$4,1,0) -> 1 | K36: =IF(K6>$Q$4,1,0) -> 1 | L36: =IF(L6>$Q$4,1,0) -> 1 | M36: =IF(M6>$Q$4,1,0) -> 0 | N36: =IF(N6>$Q$4,1,0) -> 1 | O36: =AVERAGE(J36:N36) -> 0.8
A37: 4 | B37: 1.2 | C37: 1 | D37: 1 | E37: 1 | F37: 1 | G37: =SUM(B37:F37)/5 -> 1.04 | I37: 4 | J37: =IF(J7>$Q$4,1,0) -> 1 | K37: =IF(K7>$Q$4,1,0) -> 1 | L37: =IF(L7>$Q$4,1,0) -> 0 | M37: =IF(M7>$Q$4,1,0) -> 1 | N37: =IF(N7>$Q$4,1,0) -> 1 | O37: =AVERAGE(J37:N37) -> 0.8
A38: 5 | B38: 1 | C38: 1 | D38: 1 | E38: 1 | F38: 1 | G38: =SUM(B38:F38)/5 -> 1 | I38: 5 | J38: =IF(J8>$Q$4,1,0) -> 1 | K38: =IF(K8>$Q$4,1,0) -> 1 | L38: =IF(L8>$Q$4,1,0) -> 1 | M38: =IF(M8>$Q$4,1,0) -> 1 | N38: =IF(N8>$Q$4,1,0) -> 1 | O38: =AVERAGE(J38:N38) -> 1
A39: 6 | B39: 1 | C39: 1 | D39: 1 | E39: 1 | F39: 1 | G39: =SUM(B39:F39)/5 -> 1 | I39: 6 | J39: =IF(J9>$Q$4,1,0) -> 1 | K39: =IF(K9>$Q$4,1,0) -> 1 | L39: =IF(L9>$Q$4,1,0) -> 1 | M39: =IF(M9>$Q$4,1,0) -> 1 | N39: =IF(N9>$Q$4,1,0) -> 1 | O39: =AVERAGE(J39:N39) -> 1
A40: 7 | B40: 1 | C40: 1 | D40: 1 | E40: 1 | F40: 1 | G40: =SUM(B40:F40)/5 -> 1 | I40: 7 | J40: =IF(J10>$Q$4,1,0) -> 1 | K40: =IF(K10>$Q$4,1,0) -> 1 | L40: =IF(L10>$Q$4,1,0) -> 1 | M40: =IF(M10>$Q$4,1,0) -> 1 | N40: =IF(N10>$Q$4,1,0) -> 1 | O40: =AVERAGE(J40:N40) -> 1
A41: 8 | B41: 1 | C41: 1 | D41: 1 | E41: 1 | F41: 1 | G41: =SUM(B41:F41)/5 -> 1 | I41: 8 | J41: =IF(J11>$Q$4,1,0) -> 1 | K41: =IF(K11>$Q$4,1,0) -> 1 | L41: =IF(L11>$Q$4,1,0) -> 1 | M41: =IF(M11>$Q$4,1,0) -> 1 | N41: =IF(N11>$Q$4,1,0) -> 1 | O41: =AVERAGE(J41:N41) -> 1
A42: 9 | B42: 1 | C42: 1 | D42: 1 | E42: 1 | F42: 1 | G42: =SUM(B42:F42)/5 -> 1 | I42: 9 | J42: =IF(J12>$Q$4,1,0) -> 1 | K42: =IF(K12>$Q$4,1,0) -> 1 | L42: =IF(L12>$Q$4,1,0) -> 1 | M42: =IF(M12>$Q$4,1,0) -> 1 | N42: =IF(N12>$Q$4,1,0) -> 1 | O42: =AVERAGE(J42:N42) -> 1
A43: 10 | B43: 1.2 | C43: 1 | D43: 1 | E43: 1 | F43: 1.4 | G43: =SUM(B43:F43)/5 -> 1.12 | I43: 10 | J43: =IF(J13>$Q$4,1,0) -> 1 | K43: =IF(K13>$Q$4,1,0) -> 1 | L43: =IF(L13>$Q$4,1,0) -> 1 | M43: =IF(M13>$Q$4,1,0) -> 1 | N43: =IF(N13>$Q$4,1,0) -> 1 | O43: =AVERAGE(J43:N43) -> 1
A44: 11 | B44: 1 | C44: 1 | D44: 1 | E44: 1 | F44: 1 | G44: =SUM(B44:F44)/5 -> 1 | I44: 11 | J44: =IF(J14>$Q$4,1,0) -> 1 | K44: =IF(K14>$Q$4,1,0) -> 1 | L44: =IF(L14>$Q$4,1,0) -> 1 | M44: =IF(M14>$Q$4,1,0) -> 1 | N44: =IF(N14>$Q$4,1,0) -> 1 | O44: =AVERAGE(J44:N44) -> 1
A45: 12 | B45: 1 | C45: 1 | D45: 1 | E45: 1 | F45: 1 | G45: =SUM(B45:F45)/5 -> 1 | I45: 12 | J45: =IF(J15>$Q$4,1,0) -> 1 | K45: =IF(K15>$Q$4,1,0) -> 1 | L45: =IF(L15>$Q$4,1,0) -> 0 | M45: =IF(M15>$Q$4,1,0) -> 0 | N45: =IF(N15>$Q$4,1,0) -> 1 | O45: =AVERAGE(J45:N45) -> 0.6
... A53: 20 | B53: 1 | C53: 1 | D53: 1 | E53: 1 | F53: 1 | G53: =SUM(B53:F53)/5 -> 1 | I53: 20 | J53: =IF(J23>$Q$4,1,0) -> 1 | K53: =IF(K23>$Q$4,1,0) -> 1 | L53: =IF(L23>$Q$4,1,0) -> 1 | M53: =IF(M23>$Q$4,1,0) -> 0 | N53: =IF(N23>$Q$4,1,0) -> 1 | O53: =AVERAGE(J53:N53) -> 0.8
A54: gemiddelden | B54: =MEDIAN(B34:B53) -> 1 | C54: =MEDIAN(C34:C53) -> 1 | D54: =MEDIAN(D34:D53) -> 1 | E54: =MEDIAN(E34:E53) -> 1 | F54: =MEDIAN(F34:F53) -> 1 | G54: =SUM(B54:F54)/5 -> 1 | I54: totaal | J54: =AVERAGE(J34:J53) -> 1 | K54: =AVERAGE(K34:K53) -> 1 | L54: =AVERAGE(L34:L53) -> 0.9 | M54: =AVERAGE(M34:M53) -> 0.75 | N54: =AVERAGE(N34:N53) -> 1 | O54: =AVERAGE(O34:O53) -> 0.93
A61: 0 = niks gedetecteerd
A62: 1 = well gedetecteerd
A63: falses positives | B63: test 1 | C63: test 2 | D63: test 3 | E63: test 4 | F63: test 5 | G63: totaal
A64: 1 | B64: =IF(B34>$Q$4,1,0) -> 0 | C64: =IF(C34>$Q$4,1,0) -> 0 | D64: =IF(D34>$Q$4,1,0) -> 0 | E64: =IF(E34>$Q$4,1,0) -> 0 | F64: =IF(F34>$Q$4,1,0) -> 0 | G64: =(SUM(B64:F64)/5)*100 -> 0
A65: 2 | B65: =IF(B35>$Q$4,1,0) -> 0 | C65: =IF(C35>$Q$4,1,0) -> 0 | D65: =IF(D35>$Q$4,1,0) -> 0 | E65: =IF(E35>$Q$4,1,0) -> 0 | F65: =IF(F35>$Q$4,1,0) -> 0 | G65: =(SUM(B65:F65)/5)*100 -> 0
...

Sheet ARPWatch detection method
A3: speed: begin | B3: test 1 | C3: test 2 | D3: test 3 | E3: test 4 | F3: test 5 | J3: speed: end | K3: test 1 | L3: test 2 | M3: test 3 | N3: test 4 | O3: test 5
A4: 1 | B4: 13.961545 | C4: 34.879889 | D4: 54.565485 | E4: 24.586318 | F4: 55.510421 | J4: 1 | K4: 14 | L4: 36 | M4: 55 | N4: 25 | O4: 56
A5: 2 | B5: 53.889814 | C5: 19.082575 | D5: 52.417245 | E5: 22.273349 | F5: 59.188179 | J5: 2 | K5: 54 | L5: 26 | M5: 53 | N5: 23 | O5: 60
A6: 3 | B6: 1.812976 | C6: 43.42513 | D6: 27.080027 | E6: 59.940045 | F6: 39.889878 | J6: 3 | K6: 2 | L6: 44 | M6: 28 | N6: 61 | O6: 41
A7: 4 | B7: 3.971372 | C7: 40.824094 | D7: 53.944326 | E7: 36.370875 | F7: 53.977416 | J7: 4 | K7: 5 | L7: 42 | M7: 55 | N7: 37 | O7: 55
A8: 5 | B8: 34.156953 | C8: 7.945078 | D8: 0.077383 | E8: 28.965445 | F8: 0.549409 | J8: 5 | K8: 35 | L8: 9 | M8: 1 | N8: 30 | O8: 1
A9: 6 | B9: 15.988105 | C9: 54.128719 | D9: 19.268898 | E9: 43.457415 | F9: 35.349369 | J9: 6 | K9: 17 | L9: 55 | M9: 20 | N9: 44 | O9: 36
A10: 7 | B10: 6.496761 | C10: 0.10222 | D10: 10.127971 | E10: 24.638494 | F10: 25.535851 | J10: 7 | K10: 7 | L10: 1 | M10: 11 | N10: 25 | O10: 26
A11: 8 | B11: 16.689687 | C11: 2.789545 | D11: 8.352041 | E11: 29.736385 | F11: 21.611052 | J11: 8 | K11: 17 | L11: 3 | M11: 9 | N11: 30 | O11: 22
A12: 9 | B12: 37.820734 | C12: 32.311338 | D12: 17.288254 | E12: 25.479143 | F12: 23.688238 | J12: 9 | K12: 39 | L12: 33 | M12: 18 | N12: 26 | O12: 24
A13: 10 | B13: 45.140468 | C13: 28.695907 | D13: 51.729294 | E13: 26.052386 | F13: 34.594131 | J13: 10 | K13: 46 | L13: 29 | M13: 52 | N13: 27 | O13: 35
J22: 0 = niks gedetecteerd
A23: snelheid in nano seconde | J23: 1 = well gedetecteerd
A24: speed | B24: test 1 | C24: test 2 | D24: test 3 | E24: test 4 | F24: test 5 | G24: totaal | J24: accurasy | K24: test 1 | L24: test 2 | M24: test 3 | N24: test 4 | O24: test 5 | P24: totaal
A25: 1 | B25: =(K4-B4)*1000000 -> 38455 | C25: =(L4-C4)*1000000 -> 1120111 | D25: =(M4-D4)*1000000 -> 434515 | E25: =(N4-E4)*1000000 -> 413682 | F25: =(O4-F4)*1000000 -> 489579 | G25: =SUM(B25:F25)/5 -> 499268.4 | J25: 1 | K25: 1 | L25: 1 | M25: 1 | N25: 1 | O25: 1 | P25: =MEDIAN(K25:O25) -> 1
A26: 2 | B26: =(K5-B5)*1000000 -> 110186 | C26: =(L5-C5)*1000000 -> 6917425 | D26: =(M5-D5)*1000000 -> 582755 | E26: =(N5-E5)*1000000 -> 726651 | F26: =(O5-F5)*1000000 -> 811821 | G26: =SUM(B26:F26)/5 -> 1829767.6 | J26: 2 | K26: 1 | L26: 1 | M26: 1 | N26: 1 | O26: 1 | P26: =MEDIAN(K26:O26) -> 1
A27: 3 | B27: =(K6-B6)*1000000 -> 187024 | C27: =(L6-C6)*1000000 -> 574870 | D27: =(M6-D6)*1000000 -> 919973 | E27: =(N6-E6)*1000000 -> 1059955 | F27: =(O6-F6)*1000000 -> 1110122 | G27: =SUM(B27:F27)/5 -> 770388.8 | J27: 3 | K27: 1 | L27: 1 | M27: 1 | N27: 1 | O27: 1 | P27: =MEDIAN(K27:O27) -> 1
A28: 4 | B28: =(K7-B7)*1000000 -> 1028628 | C28: =(L7-C7)*1000000 -> 1175906 | D28: =(M7-D7)*1000000 -> 1055674 | E28: =(N7-E7)*1000000 -> 629125 | F28: =(O7-F7)*1000000 -> 1022584 | G28: =SUM(B28:F28)/5 -> 982383.4 | J28: 4 | K28: 1 | L28: 1 | M28: 1 | N28: 1 | O28: 1 | P28: =MEDIAN(K28:O28) -> 1
A29: 5 | B29: =(K8-B8)*1000000 -> 843047 | C29: =(L8-C8)*1000000 -> 1054922 | D29: =(M8-D8)*1000000 -> 922617 | E29: =(N8-E8)*1000000 -> 1034555 | F29: =(O8-F8)*1000000 -> 450591 | G29: =SUM(B29:F29)/5 -> 861146.4 | J29: 5 | K29: 1 | L29: 1 | M29: 1 | N29: 1 | O29: 1 | P29: =MEDIAN(K29:O29) -> 1
A30: 6 | B30: =(K9-B9)*1000000 -> 1011895 | C30: =(L9-C9)*1000000 -> 871281 | D30: =(M9-D9)*1000000 -> 731102 | E30: =(N9-E9)*1000000 -> 542585 | F30: =(O9-F9)*1000000 -> 650631 | G30: =SUM(B30:F30)/5 -> 761498.8 | J30: 6 | K30: 1 | L30: 1 | M30: 1 | N30: 1 | O30: 1 | P30: =MEDIAN(K30:O30) -> 1
A31: 7 | B31: =(K10-B10)*1000000 -> 503239 | C31: =(L10-C10)*1000000 -> 897780 | D31: =(M10-D10)*1000000 -> 872029 | E31: =(N10-E10)*1000000 -> 361506 | F31: =(O10-F10)*1000000 -> 464149 | G31: =SUM(B31:F31)/5 -> 619740.6 | J31: 7 | K31: 1 | L31: 1 | M31: 1 | N31: 1 | O31: 1 | P31: =MEDIAN(K31:O31) -> 1
A32: 8 | B32: =(K11-B11)*1000000 -> 310313 | C32: =(L11-C11)*1000000 -> 210455 | D32: =(M11-D11)*1000000 -> 647959 | E32: =(N11-E11)*1000000 -> 263615 | F32: =(O11-F11)*1000000 -> 388948 | G32: =SUM(B32:F32)/5 -> 364258 | J32: 8 | K32: 1 | L32: 1 | M32: 1 | N32: 1 | O32: 1 | P32: =MEDIAN(K32:O32) -> 1
A33: 9 | B33: =(K12-B12)*1000000 -> 1179266 | C33: =(L12-C12)*1000000 -> 688662 | D33: =(M12-D12)*1000000 -> 711746 | E33: =(N12-E12)*1000000 -> 520857 | F33: =(O12-F12)*1000000 -> 311762 | G33: =SUM(B33:F33)/5 -> 682458.6 | J33: 9 | K33: 1 | L33: 1 | M33: 1 | N33: 1 | O33: 1 | P33: =MEDIAN(K33:O33) -> 1
A34: 10 | B34: =(K13-B13)*1000000 -> 859532 | C34: =(L13-C13)*1000000 -> 304093 | D34: =(M13-D13)*1000000 -> 270706 | E34: =(N13-E13)*1000000 -> 947614 | F34: =(O13-F13)*1000000 -> 405869 | G34: =SUM(B34:F34)/5 -> 557562.8 | J34: 10 | K34: 1 | L34: 1 | M34: 1 | N34: 1 | O34: 1 | P34: =MEDIAN(K34:O34) -> 1
A35: totaal | B35: =MEDIAN(B25:B34) -> 673143 | C35: =MEDIAN(C25:C34) -> 884530.5 | D35: =MEDIAN(D25:D34) -> 721424 | E35: =MEDIAN(E25:E34) -> 585855 | F35: =MEDIAN(F25:F34) -> 476864 | G35: =SUM(B35:F35)/5 -> 668363.3 | J35: totaal | K35: =AVERAGE(K25:K34) -> 1 | L35: =AVERAGE(L25:L34) -> 1 | M35: =AVERAGE(M25:M34) -> 1 | N35: =AVERAGE(N25:N34) -> 1 | O35: =AVERAGE(O25:O34) -> 1 | P35: =SUM(K35:O35)/5 -> 1
A44: 0 = niks gedetecteerd
A45: 1 = well gedetecteerd
A46: false positives | B46: test 1 | C46: test 2 | D46: test 3 | E46: test 4 | F46: test 5 | G46: totaal
A47: 1 | B47: 0 | C47: 0 | D47: 0 | E47: 0 | F47: 0 | G47: =(SUM(B47:F47)/5)*100 -> 0
A48: 2 | B48: 0 | C48: 0 | D48: 0 | E48: 0 | F48: 0 | G48: =(SUM(B48:F48)/5)*100 -> 0
A49: 3 | B49: 0 | C49: 0 | D49: 0 | E49: 0 | F49: 0 | G49: =(SUM(B49:F49)/5)*100 -> 0
A50: 4 | B50: 0 | C50: 0 | D50: 0 | E50: 0 | F50: 0 | G50: =(SUM(B50:F50)/5)*100 -> 0
A51: 5 | B51: 0 | C51: 0 | D51: 0 | E51: 0 | F51: 0 | G51: =(SUM(B51:F51)/5)*100 -> 0
A52: 6 | B52: 0 | C52: 0 | D52: 0 | E52: 0 | F52: 0 | G52: =(SUM(B52:F52)/5)*100 -> 0
A53: 7 | B53: 0 | C53: 0 | D53: 0 | E53: 0 | F53: 0 | G53: =(SUM(B53:F53)/5)*100 -> 0
A54: 8 | B54: 0 | C54: 0 | D54: 0 | E54: 0 | F54: 0 | G54: =(SUM(B54:F54)/5)*100 -> 0
A55: 9 | B55: 0 | C55: 0 | D55: 0 | E55: 0 | F55: 0 | G55: =(SUM(B55:F55)/5)*100 -> 0
A56: 10 | B56: 0 | C56: 0 | D56: 0 | E56: 0 | F56: 0 | G56: =(SUM(B56:F56)/5)*100 -> 0
A57: totaal | B57: =AVERAGE(B47:B56) -> 0 | C57: =AVERAGE(C47:C56) -> 0 | D57: =AVERAGE(D47:D56) -> 0 | E57: =AVERAGE(E47:E56) -> 0 | F57: =AVERAGE(F47:F56) -> 0 | G57: =SUM(B57:F57)/5 -> 0

Sheet effectiviteit
B2: speed | C2: false positves | D2: accuracy
A3: weight | B3: =0.2 -> 0.2 | C3: =0.3 -> 0.3 | D3: =0.5 -> 0.5
F4: 0 = slecht
F5: 1 = optimaal
A6: speed | B6: max speed | C6: min speed | D6: norm | F6: effectiviteit | G6: score | H6: procent score
A7: ARP | B7: =MAX('ARP detection method'!B24:F24) -> 2019138950 | C7: =MIN('ARP detection method'!B24:F24) -> 2014137300 | D7: =('ARP detection method'!G24-effectiviteit!C7)/(effectiviteit!B7-effectiviteit!C7) -> 0.38889566 | F7: ARP | G7: =D7*$B$3+D14*$C$3+D21*$D$3 -> 0.87777913 | H7: =G7*100 -> 87.777913
A8: Laytency | B8: =MAX('Laytency detection method'!B24:F24) -> 168217180 | C8: =MIN('Laytency detection method'!B24:F24) -> 136369300 | D8: =('Laytency detection method'!G24-effectiviteit!C8)/(effectiviteit!B8-effectiviteit!C8) -> 0.59021665 | F8: Laytency | G8: =D8*$B$3+D15*$C$3+D22*$D$3 -> 0.77804333 | H8: =G8*100 -> 77.804333
A9: ARP watch | B9: =MAX('ARPWatch detection method'!B35:F35) -> 884530.5 | C9: =MIN('ARPWatch detection method'!B35:F35) -> 476864 | D9: =('ARPWatch detection method'!G35-effectiviteit!C9)/(effectiviteit!B9-effectiviteit!C9) -> 0.469745 | F9: ARP watch | G9: =D9*$B$3+D16*$C$3+D23*$D$3 -> 0.893949 | H9: =G9*100 -> 89.3949
A13: false positives | B13: max speed | C13: min speed | D13: norm
A14: ARP | B14: =MAX('ARP detection method'!B50:F50) -> 0 | C14: =MIN('ARP detection method'!B50:F50) -> 0 | D14: =IF((effectiviteit!B14-effectiviteit!C14)=0,1,('ARP detection method'!G50-C14)/(B14-C14)) -> 1
A15: Laytency | B15: =MAX('Laytency detection method'!B84:F84) -> 0 | C15: =MIN('Laytency detection method'!B84:F84) -> 0 | D15: =IF((effectiviteit!B15-effectiviteit!C15)=0,1,('ARP detection method'!G51-C15)/(B15-C15)) -> 1
A16: ARP watch | B16: =MAX('ARPWatch detection method'!B57:F57) -> 0 | C16: =MIN('ARPWatch detection method'!B57:F57) -> 0 | D16: =IF((effectiviteit!B16-effectiviteit!C16)=0,1,('ARP detection method'!G52-C16)/(B16-C16)) -> 1
A20: accuracy | B20: max speed | C20: min speed | D20: norm
A21: ARP | B21: =MAX('ARP detection method'!J24:N24) -> 1 | C21: =MIN('ARP detection method'!J24:N24) -> 1 | D21: =IF((effectiviteit!B21-effectiviteit!C21)=0,1,('ARP detection method'!O24-C21)/(B21-C21)) -> 1
A22: Laytency | B22: =MAX('Laytency detection method'!J54:N54) -> 1 | C22: =MIN('Laytency detection method'!J54:N54) -> 0.75 | D22: =IF((effectiviteit!B22-effectiviteit!C22)=0,1,('Laytency detection method'!O54-C22)/(B22-C22)) -> 0.72
A23: ARP watch | B23: =MAX('ARPWatch detection method'!K35:O35) -> 1 | C23: =MIN('ARPWatch detection method'!K35:O35) -> 1 | D23: =IF((effectiviteit!B23-effectiviteit!C23)=0,1,('ARPWatch detection method'!P35-C23)/(B23-C23)) -> 1

Sheet HTTPS
A1: Test 1 | E1: test 2 | I1: test 3 | M1: test 4 | Q1: test 5
A3: MITM,HTTP_packets,TLS_packets | E3: MITM,HTTP_packets,TLS_packets | I3: MITM,HTTP_packets,TLS_packets | M3: MITM,HTTP_packets,TLS_packets | Q3: MITM | R3: HTTP_packets | S3: TLS_packets
A4: 1 | B4: 0 | C4: 48 | E4: 1 | F4: 0 | G4: 48 | I4: 1 | J4: 0 | K4: 48 | M4: 1 | N4: 0 | O4: 42 | Q4: 1 | R4: 0 | S4: 48
A5: 1 | B5: 0 | C5: 54 | E5: 1 | F5: 0 | G5: 54 | I5: 1 | J5: 0 | K5: 48 | M5: 1 | N5: 0 | O5: 54 | Q5: 1 | R5: 0 | S5: 48
A6: 1 | B6: 0 | C6: 48 | E6: 1 | F6: 0 | G6: 42 | I6: 1 | J6: 0 | K6: 54 | M6: 1 | N6: 0 | O6: 48 | Q6: 1 | R6: 0 | S6: 48
A7: 1 | B7: 0 | C7: 48 | E7: 1 | F7: 0 | G7: 48 | I7: 1 | J7: 0 | K7: 48 | M7: 1 | N7: 0 | O7: 54 | Q7: 1 | R7: 0 | S7: 42
A8: 1 | B8: 0 | C8: 48 | E8: 1 | F8: 0 | G8: 48 | I8: 1 | J8: 0 | K8: 48 | M8: 1 | N8: 0 | O8: 48 | Q8: 1 | R8: 0 | S8: 42
A9: 1 | B9: 0 | C9: 42 | E9: 1 | F9: 0 | G9: 48 | I9: 1 | J9: 0 | K9: 48 | M9: 1 | N9: 0 | O9: 48 | Q9: 1 | R9: 0 | S9: 48
A10: 1 | B10: 0 | C10: 48 | E10: 1 | F10: 0 | G10: 48 | I10: 1 | J10: 0 | K10: 48 | M10: 1 | N10: 0 | O10: 54 | Q10: 1 | R10: 0 | S10: 48
A11: 1 | B11: 0 | C11: 54 | E11: 1 | F11: 0 | G11: 48 | I11: 1 | J11: 0 | K11: 48 | M11: 1 | N11: 0 | O11: 54 | Q11: 1 | R11: 0 | S11: 48
A12: 1 | B12: 0 | C12: 48 | E12: 1 | F12: 0 | G12: 48 | I12: 1 | J12: 0 | K12: 48 | M12: 1 | N12: 0 | O12: 48 | Q12: 1 | R12: 0 | S12: 42
A13: 1 | B13: 0 | C13: 48 | E13: 1 | F13: 0 | G13: 48 | I13: 1 | J13: 0 | K13: 48 | M13: 1 | N13: 0 | O13: 48 | Q13: 1 | R13: 0 | S13: 48
A14: 1 | B14: 0 | C14: 48 | E14: 1 | F14: 0 | G14: 24 | I14: 1 | J14: 0 | K14: 48 | M14: 1 | N14: 0 | O14: 48 | Q14: 1 | R14: 0 | S14: 48
A15: 1 | B15: 0 | C15: 48 | E15: 1 | F15: 0 | G15: 48 | I15: 1 | J15: 0 | K15: 48 | M15: 1 | N15: 0 | O15: 48 | Q15: 1 | R15: 0 | S15: 48
... A23: 1 | B23: 0 | C23: 54 | E23: 1 | F23: 0 | G23: 48 | I23: 1 | J23: 0 | K23: 48 | M23: 1 | N23: 0 | O23: 54 | Q23: 1 | R23: 0 | S23: 42
A27: MITM detcted | B27: test 1 | C27: test 2 | D27: test 3 | E27: test 4 | F27: test 5 | G27: totaal | I27: HTTP packets | J27: test 1 | K27: test 2 | L27: test 3 | M27: test 4 | N27: test 5 | P27: TLS packets | Q27: test 1 | R27: test 2 | S27: test 3 | T27: test 4 | U27: test 5
A28: 1 | B28: =A4 -> 1 | C28: =E4 -> 1 | D28: =I4 -> 1 | E28: =M4 -> 1 | F28: =Q4 -> 1 | G28: =SUM(B28:F28) -> 5 | I28: 1 | J28: =B4 -> 0 | K28: =F4 -> 0 | L28: =J4 -> 0 | M28: =N4 -> 0 | N28: =R4 -> 0 | P28: 1 | Q28: =C4 -> 48 | R28: =G4 -> 48 | S28: =K4 -> 48 | T28: =O4 -> 42 | U28: =S4 -> 48
A29: 2 | B29: =A5 -> 1 | C29: =E5 -> 1 | D29: =I5 -> 1 | E29: =M5 -> 1 | F29: =Q5 -> 1 | G29: =SUM(B29:F29) -> 5 | I29: 2 | J29: =B5 -> 0 | K29: =F5 -> 0 | L29: =J5 -> 0 | M29: =N5 -> 0 | N29: =R5 -> 0 | P29: 2 | Q29: =C5 -> 54 | R29: =G5 -> 54 | S29: =K5 -> 48 | T29: =O5 -> 54 | U29: =S5 -> 48
A30: 3 | B30: =A6 -> 1 | C30: =E6 -> 1 | D30: =I6 -> 1 | E30: =M6 -> 1 | F30: =Q6 -> 1 | G30: =SUM(B30:F30) -> 5 | I30: 3 | J30: =B6 -> 0 | K30: =F6 -> 0 | L30: =J6 -> 0 | M30: =N6 -> 0 | N30: =R6 -> 0 | P30: 3 | Q30: =C6 -> 48 | R30: =G6 -> 42 | S30: =K6 -> 54 | T30: =O6 -> 48 | U30: =S6 -> 48
A31: 4 | B31: =A7 -> 1 | C31: =E7 -> 1 | D31: =I7 -> 1 | E31: =M7 -> 1 | F31: =Q7 -> 1 | G31: =SUM(B31:F31) -> 5 | I31: 4 | J31: =B7 -> 0 | K31: =F7 -> 0 | L31: =J7 -> 0 | M31: =N7 -> 0 | N31: =R7 -> 0 | P31: 4 | Q31: =C7 -> 48 | R31: =G7 -> 48 | S31: =K7 -> 48 | T31: =O7 -> 54 | U31: =S7 -> 42
A32: 5 | B32: =A8 -> 1 | C32: =E8 -> 1 | D32: =I8 -> 1 | E32: =M8 -> 1 | F32: =Q8 -> 1 | G32: =SUM(B32:F32) -> 5 | I32: 5 | J32: =B8 -> 0 | K32: =F8 -> 0 | L32: =J8 -> 0 | M32: =N8 -> 0 | N32: =R8 -> 0 | P32: 5 | Q32: =C8 -> 48 | R32: =G8 -> 48 | S32: =K8 -> 48 | T32: =O8 -> 48 | U32: =S8 -> 42
A33: 6 | B33: =A9 -> 1 | C33: =E9 -> 1 | D33: =I9 -> 1 | E33: =M9 -> 1 | F33: =Q9 -> 1 | G33: =SUM(B33:F33) -> 5 | I33: 6 | J33: =B9 -> 0 | K33: =F9 -> 0 | L33: =J9 -> 0 | M33: =N9 -> 0 | N33: =R9 -> 0 | P33: 6 | Q33: =C9 -> 42 | R33: =G9 -> 48 | S33: =K9 -> 48 | T33: =O9 -> 48 | U33: =S9 -> 48
A34: 7 | B34: =A10 -> 1 | C34: =E10 -> 1 | D34: =I10 -> 1 | E34: =M10 -> 1 | F34: =Q10 -> 1 | G34: =SUM(B34:F34) -> 5 | I34: 7 | J34: =B10 -> 0 | K34: =F10 -> 0 | L34: =J10 -> 0 | M34: =N10 -> 0 | N34: =R10 -> 0 | P34: 7 | Q34: =C10 -> 48 | R34: =G10 -> 48 | S34: =K10 -> 48 | T34: =O10 -> 54 | U34: =S10 -> 48
A35: 8 | B35: =A11 -> 1 | C35: =E11 -> 1 | D35: =I11 -> 1 | E35: =M11 -> 1 | F35: =Q11 -> 1 | G35: =SUM(B35:F35) -> 5 | I35: 8 | J35: =B11 -> 0 | K35: =F11 -> 0 | L35: =J11 -> 0 | M35: =N11 -> 0 | N35: =R11 -> 0 | P35: 8 | Q35: =C11 -> 54 | R35: =G11 -> 48 | S35: =K11 -> 48 | T35: =O11 -> 54 | U35: =S11 -> 48
A36: 9 | B36: =A12 -> 1 | C36: =E12 -> 1 | D36: =I12 -> 1 | E36: =M12 -> 1 | F36: =Q12 -> 1 | G36: =SUM(B36:F36) -> 5 | I36: 9 | J36: =B12 -> 0 | K36: =F12 -> 0 | L36: =J12 -> 0 | M36: =N12 -> 0 | N36: =R12 -> 0 | P36: 9 | Q36: =C12 -> 48 | R36: =G12 -> 48 | S36: =K12 -> 48 | T36: =O12 -> 48 | U36: =S12 -> 42
A37: 10 | B37: =A13 -> 1 | C37: =E13 -> 1 | D37: =I13 -> 1 | E37: =M13 -> 1 | F37: =Q13 -> 1 | G37: =SUM(B37:F37) -> 5 | I37: 10 | J37: =B13 -> 0 | K37: =F13 -> 0 | L37: =J13 -> 0 | M37: =N13 -> 0 | N37: =R13 -> 0 | P37: 10 | Q37: =C13 -> 48 | R37: =G13 -> 48 | S37: =K13 -> 48 | T37: =O13 -> 48 | U37: =S13 -> 48
A38: 11 | B38: =A14 -> 1 | C38: =E14 -> 1 | D38: =I14 -> 1 | E38: =M14 -> 1 | F38: =Q14 -> 1 | G38: =SUM(B38:F38) -> 5 | I38: 11 | J38: =B14 -> 0 | K38: =F14 -> 0 | L38: =J14 -> 0 | M38: =N14 -> 0 | N38: =R14 -> 0 | P38: 11 | Q38: =C14 -> 48 | R38: =G14 -> 24 | S38: =K14 -> 48 | T38: =O14 -> 48 | U38: =S14 -> 48
A39: 12 | B39: =A15 -> 1 | C39: =E15 -> 1 | D39: =I15 -> 1 | E39: =M15 -> 1 | F39: =Q15 -> 1 | G39: =SUM(B39:F39) -> 5 | I39: 12 | J39: =B15 -> 0 | K39: =F15 -> 0 | L39: =J15 -> 0 | M39: =N15 -> 0 | N39: =R15 -> 0 | P39: 12 | Q39: =C15 -> 48 | R39: =G15 -> 48 | S39: =K15 -> 48 | T39: =O15 -> 48 | U39: =S15 -> 48
... A47: 20 | B47: =A23 -> 1 | C47: =E23 -> 1 | D47: =I23 -> 1 | E47: =M23 -> 1 | F47: =Q23 -> 1 | G47: =SUM(B47:F47) -> 5 | I47: 20 | J47: =B23 -> 0 | K47: =F23 -> 0 | L47: =J23 -> 0 | M47: =N23 -> 0 | N47: =R23 -> 0 | P47: 20 | Q47: =C23 -> 54 | R47: =G23 -> 48 | S47: =K23 -> 48 | T47: =O23 -> 54 | U47: =S23 -> 42
A48: totaal | B48: =SUM(B28:B47) -> 20 | C48: =SUM(C28:C47) -> 20 | D48: =SUM(D28:D47) -> 20 | E48: =SUM(E28:E47) -> 20 | F48: =SUM(F28:F47) -> 20 | G48: =SUM(B48:F48) -> 100
A53: Can be modified | B53: test 1 | C53: test 2 | D53: test 3 | E53: test 4 | F53: test 5 | G53: totaal
A54: 1 | B54: =IF(J28=0,0,1) -> 0 | C54: =IF(K28=0,0,1) -> 0 | D54: =IF(L28=0,0,1) -> 0 | E54: =IF(M28=0,0,1) -> 0 | F54: =IF(N28=0,0,1) -> 0 | G54: =SUM(B54:F54) -> 0
A55: 2 | B55: =IF(J29=0,0,1) -> 0 | C55: =IF(K29=0,0,1) -> 0 | D55: =IF(L29=0,0,1) -> 0 | E55: =IF(M29=0,0,1) -> 0 | F55: =IF(N29=0,0,1) -> 0 | G55: =SUM(B55:F55) -> 0
A56: 3 | B56: =IF(J30=0,0,1) -> 0 | C56: =IF(K30=0,0,1) -> 0 | D56: =IF(L30=0,0,1) -> 0 | E56: =IF(M30=0,0,1) -> 0 | F56: =IF(N30=0,0,1) -> 0 | G56: =SUM(B56:F56) -> 0
A57: 4 | B57: =IF(J31=0,0,1) -> 0 | C57: =IF(K31=0,0,1) -> 0 | D57: =IF(L31=0,0,1) -> 0 | E57: =IF(M31=0,0,1) -> 0 | F57: =IF(N31=0,0,1) -> 0 | G57: =SUM(B57:F57) -> 0
A58: 5 | B58: =IF(J32=0,0,1) -> 0 | C58: =IF(K32=0,0,1) -> 0 | D58: =IF(L32=0,0,1) -> 0 | E58: =IF(M32=0,0,1) -> 0 | F58: =IF(N32=0,0,1) -> 0 | G58: =SUM(B58:F58) -> 0
A59: 6 | B59: =IF(J33=0,0,1) -> 0 | C59: =IF(K33=0,0,1) -> 0 | D59: =IF(L33=0,0,1) -> 0 | E59: =IF(M33=0,0,1) -> 0 | F59: =IF(N33=0,0,1) -> 0 | G59: =SUM(B59:F59) -> 0
A60: 7 | B60: =IF(J34=0,0,1) -> 0 | C60: =IF(K34=0,0,1) -> 0 | D60: =IF(L34=0,0,1) -> 0 | E60: =IF(M34=0,0,1) -> 0 | F60: =IF(N34=0,0,1) -> 0 | G60: =SUM(B60:F60) -> 0
A61: 8 | B61: =IF(J35=0,0,1) -> 0 | C61: =IF(K35=0,0,1) -> 0 | D61: =IF(L35=0,0,1) -> 0 | E61: =IF(M35=0,0,1) -> 0 | F61: =IF(N35=0,0,1) -> 0 | G61: =SUM(B61:F61) -> 0
A62: 9 | B62: =IF(J36=0,0,1) -> 0 | C62: =IF(K36=0,0,1) -> 0 | D62: =IF(L36=0,0,1) -> 0 | E62: =IF(M36=0,0,1) -> 0 | F62: =IF(N36=0,0,1) -> 0 | G62: =SUM(B62:F62) -> 0
...

Sheet Static ARP entrys
A1: Test 1 | E1: test 2 | I1: test 3 | M1: test 4 | Q1: test 5
A3: MITM,HTTP_packets,TLS_packets | E3: MITM,HTTP_packets,TLS_packets | I3: MITM,HTTP_packets,TLS_packets | M3: MITM,HTTP_packets,TLS_packets | Q3: MITM | R3: HTTP_packets | S3: TLS_packets
A4: 0 | B4: 0 | C4: 0 | E4: 0 | F4: 0 | G4: 0 | I4: 0 | J4: 0 | K4: 0 | M4: 0 | N4: 0 | O4: 0 | Q4: 0 | R4: 0 | S4: 0
A5: 0 | B5: 0 | C5: 0 | E5: 0 | F5: 0 | G5: 0 | I5: 0 | J5: 0 | K5: 0 | M5: 0 | N5: 0 | O5: 0 | Q5: 0 | R5: 0 | S5: 0
A6: 0 | B6: 0 | C6: 0 | E6: 0 | F6: 0 | G6: 0 | I6: 0 | J6: 0 | K6: 0 | M6: 0 | N6: 0 | O6: 0 | Q6: 0 | R6: 0 | S6: 0
A7: 0 | B7: 0 | C7: 0 | E7: 0 | F7: 0 | G7: 0 | I7: 0 | J7: 0 | K7: 0 | M7: 0 | N7: 0 | O7: 0 | Q7: 0 | R7: 0 | S7: 0
A8: 0 | B8: 0 | C8: 0 | E8: 0 | F8: 0 | G8: 0 | I8: 0 | J8: 0 | K8: 0 | M8: 0 | N8: 0 | O8: 0 | Q8: 0 | R8: 0 | S8: 0
A9: 0 | B9: 0 | C9: 0 | E9: 0 | F9: 0 | G9: 0 | I9: 0 | J9: 0 | K9: 0 | M9: 0 | N9: 0 | O9: 0 | Q9: 0 | R9: 0 | S9: 0
A10: 0 | B10: 0 | C10: 0 | E10: 0 | F10: 0 | G10: 0 | I10: 0 | J10: 0 | K10: 0 | M10: 0 | N10: 0 | O10: 0 | Q10: 0 | R10: 0 | S10: 0
A11: 0 | B11: 0 | C11: 0 | E11: 0 | F11: 0 | G11: 0 | I11: 0 | J11: 0 | K11: 0 | M11: 0 | N11: 0 | O11: 0 | Q11: 0 | R11: 0 | S11: 0
A12: 0 | B12: 0 | C12: 0 | E12: 0 | F12: 0 | G12: 0 | I12: 0 | J12: 0 | K12: 0 | M12: 0 | N12: 0 | O12: 0 | Q12: 0 | R12: 0 | S12: 0
A13: 0 | B13: 0 | C13: 0 | E13: 0 | F13: 0 | G13: 0 | I13: 0 | J13: 0 | K13: 0 | M13: 0 | N13: 0 | O13: 0 | Q13: 0 | R13: 0 | S13: 0
A14: 0 | B14: 0 | C14: 0 | E14: 0 | F14: 0 | G14: 0 | I14: 0 | J14: 0 | K14: 0 | M14: 0 | N14: 0 | O14: 0 | Q14: 0 | R14: 0 | S14: 0
A15: 0 | B15: 0 | C15: 0 | E15: 0 | F15: 0 | G15: 0 | I15: 0 | J15: 0 | K15: 0 | M15: 0 | N15: 0 | O15: 0 | Q15: 0 | R15: 0 | S15: 0
... A23: 0 | B23: 0 | C23: 0 | E23: 0 | F23: 0 | G23: 0 | I23: 0 | J23: 0 | K23: 0 | M23: 0 | N23: 0 | O23: 0 | Q23: 0 | R23: 0 | S23: 0
A27: MITM detcted | B27: test 1 | C27: test 2 | D27: test 3 | E27: test 4 | F27: test 5 | G27: totaal | I27: HTTP packets | J27: test 1 | K27: test 2 | L27: test 3 | M27: test 4 | N27: test 5 | P27: TLS packets | Q27: test 1 | R27: test 2 | S27: test 3 | T27: test 4 | U27: test 5
A28: 1 | B28: =A4 -> 0 | C28: =E4 -> 0 | D28: =I4 -> 0 | E28: =M4 -> 0 | F28: =Q4 -> 0 | G28: =SUM(B28:F28) -> 0 | I28: 1 | J28: =B4 -> 0 | K28: =F4 -> 0 | L28: =J4 -> 0 | M28: =N4 -> 0 | N28: =R4 -> 0 | P28: 1 | Q28: =C4 -> 0 | R28: =G4 -> 0 | S28: =K4 -> 0 | T28: =O4 -> 0 | U28: =S4 -> 0
A29: 2 | B29: =A5 -> 0 | C29: =E5 -> 0 | D29: =I5 -> 0 | E29: =M5 -> 0 | F29: =Q5 -> 0 | G29: =SUM(B29:F29) -> 0 | I29: 2 | J29: =B5 -> 0 | K29: =F5 -> 0 | L29: =J5 -> 0 | M29: =N5 -> 0 | N29: =R5 -> 0 | P29: 2 | Q29: =C5 -> 0 | R29: =G5 -> 0 | S29: =K5 -> 0 | T29: =O5 -> 0 | U29: =S5 -> 0
A30: 3 | B30: =A6 -> 0 | C30: =E6 -> 0 | D30: =I6 -> 0 | E30: =M6 -> 0 | F30: =Q6 -> 0 | G30: =SUM(B30:F30) -> 0 | I30: 3 | J30: =B6 -> 0 | K30: =F6 -> 0 | L30: =J6 -> 0 | M30: =N6 -> 0 | N30: =R6 -> 0 | P30: 3 | Q30: =C6 -> 0 | R30: =G6 -> 0 | S30: =K6 -> 0 | T30: =O6 -> 0 | U30: =S6 -> 0
A31: 4 | B31: =A7 -> 0 | C31: =E7 -> 0 | D31: =I7 -> 0 | E31: =M7 -> 0 | F31: =Q7 -> 0 | G31: =SUM(B31:F31) -> 0 | I31: 4 | J31: =B7 -> 0 | K31: =F7 -> 0 | L31: =J7 -> 0 | M31: =N7 -> 0 | N31: =R7 -> 0 | P31: 4 | Q31: =C7 -> 0 | R31: =G7 -> 0 | S31: =K7 -> 0 | T31: =O7 -> 0 | U31: =S7 -> 0
A32: 5 | B32: =A8 -> 0 | C32: =E8 -> 0 | D32: =I8 -> 0 | E32: =M8 -> 0 | F32: =Q8 -> 0 | G32: =SUM(B32:F32) -> 0 | I32: 5 | J32: =B8 -> 0 | K32: =F8 -> 0 | L32: =J8 -> 0 | M32: =N8 -> 0 | N32: =R8 -> 0 | P32: 5 | Q32: =C8 -> 0 | R32: =G8 -> 0 | S32: =K8 -> 0 | T32: =O8 -> 0 | U32: =S8 -> 0
A33: 6 | B33: =A9 -> 0 | C33: =E9 -> 0 | D33: =I9 -> 0 | E33: =M9 -> 0 | F33: =Q9 -> 0 | G33: =SUM(B33:F33) -> 0 | I33: 6 | J33: =B9 -> 0 | K33: =F9 -> 0 | L33: =J9 -> 0 | M33: =N9 -> 0 | N33: =R9 -> 0 | P33: 6 | Q33: =C9 -> 0 | R33: =G9 -> 0 | S33: =K9 -> 0 | T33: =O9 -> 0 | U33: =S9 -> 0
A34: 7 | B34: =A10 -> 0 | C34: =E10 -> 0 | D34: =I10 -> 0 | E34: =M10 -> 0 | F34: =Q10 -> 0 | G34: =SUM(B34:F34) -> 0 | I34: 7 | J34: =B10 -> 0 | K34: =F10 -> 0 | L34: =J10 -> 0 | M34: =N10 -> 0 | N34: =R10 -> 0 | P34: 7 | Q34: =C10 -> 0 | R34: =G10 -> 0 | S34: =K10 -> 0 | T34: =O10 -> 0 | U34: =S10 -> 0
A35: 8 | B35: =A11 -> 0 | C35: =E11 -> 0 | D35: =I11 -> 0 | E35: =M11 -> 0 | F35: =Q11 -> 0 | G35: =SUM(B35:F35) -> 0 | I35: 8 | J35: =B11 -> 0 | K35: =F11 -> 0 | L35: =J11 -> 0 | M35: =N11 -> 0 | N35: =R11 -> 0 | P35: 8 | Q35: =C11 -> 0 | R35: =G11 -> 0 | S35: =K11 -> 0 | T35: =O11 -> 0 | U35: =S11 -> 0
A36: 9 | B36: =A12 -> 0 | C36: =E12 -> 0 | D36: =I12 -> 0 | E36: =M12 -> 0 | F36: =Q12 -> 0 | G36: =SUM(B36:F36) -> 0 | I36: 9 | J36: =B12 -> 0 | K36: =F12 -> 0 | L36: =J12 -> 0 | M36: =N12 -> 0 | N36: =R12 -> 0 | P36: 9 | Q36: =C12 -> 0 | R36: =G12 -> 0 | S36: =K12 -> 0 | T36: =O12 -> 0 | U36: =S12 -> 0
A37: 10 | B37: =A13 -> 0 | C37: =E13 -> 0 | D37: =I13 -> 0 | E37: =M13 -> 0 | F37: =Q13 -> 0 | G37: =SUM(B37:F37) -> 0 | I37: 10 | J37: =B13 -> 0 | K37: =F13 -> 0 | L37: =J13 -> 0 | M37: =N13 -> 0 | N37: =R13 -> 0 | P37: 10 | Q37: =C13 -> 0 | R37: =G13 -> 0 | S37: =K13 -> 0 | T37: =O13 -> 0 | U37: =S13 -> 0
A38: 11 | B38: =A14 -> 0 | C38: =E14 -> 0 | D38: =I14 -> 0 | E38: =M14 -> 0 | F38: =Q14 -> 0 | G38: =SUM(B38:F38) -> 0 | I38: 11 | J38: =B14 -> 0 | K38: =F14 -> 0 | L38: =J14 -> 0 | M38: =N14 -> 0 | N38: =R14 -> 0 | P38: 11 | Q38: =C14 -> 0 | R38: =G14 -> 0 | S38: =K14 -> 0 | T38: =O14 -> 0 | U38: =S14 -> 0
A39: 12 | B39: =A15 -> 0 | C39: =E15 -> 0 | D39: =I15 -> 0 | E39: =M15 -> 0 | F39: =Q15 -> 0 | G39: =SUM(B39:F39) -> 0 | I39: 12 | J39: =B15 -> 0 | K39: =F15 -> 0 | L39: =J15 -> 0 | M39: =N15 -> 0 | N39: =R15 -> 0 | P39: 12 | Q39: =C15 -> 0 | R39: =G15 -> 0 | S39: =K15 -> 0 | T39: =O15 -> 0 | U39: =S15 -> 0
... A47: 20 | B47: =A23 -> 0 | C47: =E23 -> 0 | D47: =I23 -> 0 | E47: =M23 -> 0 | F47: =Q23 -> 0 | G47: =SUM(B47:F47) -> 0 | I47: 20 | J47: =B23 -> 0 | K47: =F23 -> 0 | L47: =J23 -> 0 | M47: =N23 -> 0 | N47: =R23 -> 0 | P47: 20 | Q47: =C23 -> 0 | R47: =G23 -> 0 | S47: =K23 -> 0 | T47: =O23 -> 0 | U47: =S23 -> 0
A48: totaal | B48: =SUM(B28:B47) -> 0 | C48: =SUM(C28:C47) -> 0 | D48: =SUM(D28:D47) -> 0 | E48: =SUM(E28:E47) -> 0 | F48: =SUM(F28:F47) -> 0 | G48: =SUM(B48:F48) -> 0
A53: Can be modified | B53: test 1 | C53: test 2 | D53: test 3 | E53: test 4 | F53: test 5 | G53: totaal
A54: 1 | B54: =IF(J28=0,0,1) -> 0 | C54: =IF(K28=0,0,1) -> 0 | D54: =IF(L28=0,0,1) -> 0 | E54: =IF(M28=0,0,1) -> 0 | F54: =IF(N28=0,0,1) -> 0 | G54: =SUM(B54:F54) -> 0
A55: 2 | B55: =IF(J29=0,0,1) -> 0 | C55: =IF(K29=0,0,1) -> 0 | D55: =IF(L29=0,0,1) -> 0 | E55: =IF(M29=0,0,1) -> 0 | F55: =IF(N29=0,0,1) -> 0 | G55: =SUM(B55:F55) -> 0
A56: 3 | B56: =IF(J30=0,0,1) -> 0 | C56: =IF(K30=0,0,1) -> 0 | D56: =IF(L30=0,0,1) -> 0 | E56: =IF(M30=0,0,1) -> 0 | F56: =IF(N30=0,0,1) -> 0 | G56: =SUM(B56:F56) -> 0
A57: 4 | B57: =IF(J31=0,0,1) -> 0 | C57: =IF(K31=0,0,1) -> 0 | D57: =IF(L31=0,0,1) -> 0 | E57: =IF(M31=0,0,1) -> 0 | F57: =IF(N31=0,0,1) -> 0 | G57: =SUM(B57:F57) -> 0
A58: 5 | B58: =IF(J32=0,0,1) -> 0 | C58: =IF(K32=0,0,1) -> 0 | D58: =IF(L32=0,0,1) -> 0 | E58: =IF(M32=0,0,1) -> 0 | F58: =IF(N32=0,0,1) -> 0 | G58: =SUM(B58:F58) -> 0
A59: 6 | B59: =IF(J33=0,0,1) -> 0 | C59: =IF(K33=0,0,1) -> 0 | D59: =IF(L33=0,0,1) -> 0 | E59: =IF(M33=0,0,1) -> 0 | F59: =IF(N33=0,0,1) -> 0 | G59: =SUM(B59:F59) -> 0
A60: 7 | B60: =IF(J34=0,0,1) -> 0 | C60: =IF(K34=0,0,1) -> 0 | D60: =IF(L34=0,0,1) -> 0 | E60: =IF(M34=0,0,1) -> 0 | F60: =IF(N34=0,0,1) -> 0 | G60: =SUM(B60:F60) -> 0
A61: 8 | B61: =IF(J35=0,0,1) -> 0 | C61: =IF(K35=0,0,1) -> 0 | D61: =IF(L35=0,0,1) -> 0 | E61: =IF(M35=0,0,1) -> 0 | F61: =IF(N35=0,0,1) -> 0 | G61: =SUM(B61:F61) -> 0
A62: 9 | B62: =IF(J36=0,0,1) -> 0 | C62: =IF(K36=0,0,1) -> 0 | D62: =IF(L36=0,0,1) -> 0 | E62: =IF(M36=0,0,1) -> 0 | F62: =IF(N36=0,0,1) -> 0 | G62: =SUM(B62:F62) -> 0
...

Sheet VLANs
A1: Test 1 | E1: test 2 | I1: test 3 | M1: test 4 | Q1: test 5
A3: MITM,HTTP_packets,TLS_packets | E3: MITM,HTTP_packets,TLS_packets | I3: MITM,HTTP_packets,TLS_packets | M3: MITM,HTTP_packets,TLS_packets | Q3: MITM | R3: HTTP_packets | S3: TLS_packets
A4: 0 | B4: 0 | C4: 0 | E4: 0 | F4: 0 | G4: 0 | I4: 0 | J4: 0 | K4: 0 | M4: 0 | N4: 0 | O4: 0 | Q4: 0 | R4: 0 | S4: 0
A5: 0 | B5: 0 | C5: 0 | E5: 0 | F5: 0 | G5: 0 | I5: 0 | J5: 0 | K5: 0 | M5: 0 | N5: 0 | O5: 0 | Q5: 0 | R5: 0 | S5: 0
A6: 0 | B6: 0 | C6: 0 | E6: 0 | F6: 0 | G6: 0 | I6: 0 | J6: 0 | K6: 0 | M6: 0 | N6: 0 | O6: 0 | Q6: 0 | R6: 0 | S6: 0
A7: 0 | B7: 0 | C7: 0 | E7: 0 | F7: 0 | G7: 0 | I7: 0 | J7: 0 | K7: 0 | M7: 0 | N7: 0 | O7: 0 | Q7: 0 | R7: 0 | S7: 0
A8: 0 | B8: 0 | C8: 0 | E8: 0 | F8: 0 | G8: 0 | I8: 0 | J8: 0 | K8: 0 | M8: 0 | N8: 0 | O8: 0 | Q8: 0 | R8: 0 | S8: 0
A9: 0 | B9: 0 | C9: 0 | E9: 0 | F9: 0 | G9: 0 | I9: 0 | J9: 0 | K9: 0 | M9: 0 | N9: 0 | O9: 0 | Q9: 0 | R9: 0 | S9: 0
A10: 0 | B10: 0 | C10: 0 | E10: 0 | F10: 0 | G10: 0 | I10: 0 | J10: 0 | K10: 0 | M10: 0 | N10: 0 | O10: 0 | Q10: 0 | R10: 0 | S10: 0
A11: 0 | B11: 0 | C11: 0 | E11: 0 | F11: 0 | G11: 0 | I11: 0 | J11: 0 | K11: 0 | M11: 0 | N11: 0 | O11: 0 | Q11: 0 | R11: 0 | S11: 0
A12: 0 | B12: 0 | C12: 0 | E12: 0 | F12: 0 | G12: 0 | I12: 0 | J12: 0 | K12: 0 | M12: 0 | N12: 0 | O12: 0 | Q12: 0 | R12: 0 | S12: 0
A13: 0 | B13: 0 | C13: 0 | E13: 0 | F13: 0 | G13: 0 | I13: 0 | J13: 0 | K13: 0 | M13: 0 | N13: 0 | O13: 0 | Q13: 0 | R13: 0 | S13: 0
A14: 0 | B14: 0 | C14: 0 | E14: 0 | F14: 0 | G14: 0 | I14: 0 | J14: 0 | K14: 0 | M14: 0 | N14: 0 | O14: 0 | Q14: 0 | R14: 0 | S14: 0
A15: 0 | B15: 0 | C15: 0 | E15: 0 | F15: 0 | G15: 0 | I15: 0 | J15: 0 | K15: 0 | M15: 0 | N15: 0 | O15: 0 | Q15: 0 | R15: 0 | S15: 0
... A23: 0 | B23: 0 | C23: 0 | E23: 0 | F23: 0 | G23: 0 | I23: 0 | J23: 0 | K23: 0 | M23: 0 | N23: 0 | O23: 0 | Q23: 0 | R23: 0 | S23: 0
A27: MITM detcted | B27: test 1 | C27: test 2 | D27: test 3 | E27: test 4 | F27: test 5 | G27: totaal | I27: HTTP packets | J27: test 1 | K27: test 2 | L27: test 3 | M27: test 4 | N27: test 5 | P27: TLS packets | Q27: test 1 | R27: test 2 | S27: test 3 | T27: test 4 | U27: test 5
A28: 1 | B28: =A4 -> 0 | C28: =E4 -> 0 | D28: =I4 -> 0 | E28: =M4 -> 0 | F28: =Q4 -> 0 | G28: =SUM(B28:F28) -> 0 | I28: 1 | J28: =B4 -> 0 | K28: =F4 -> 0 | L28: =J4 -> 0 | M28: =N4 -> 0 | N28: =R4 -> 0 | P28: 1 | Q28: =C4 -> 0 | R28: =G4 -> 0 | S28: =K4 -> 0 | T28: =O4 -> 0 | U28: =S4 -> 0
A29: 2 | B29: =A5 -> 0 | C29: =E5 -> 0 | D29: =I5 -> 0 | E29: =M5 -> 0 | F29: =Q5 -> 0 | G29: =SUM(B29:F29) -> 0 | I29: 2 | J29: =B5 -> 0 | K29: =F5 -> 0 | L29: =J5 -> 0 | M29: =N5 -> 0 | N29: =R5 -> 0 | P29: 2 | Q29: =C5 -> 0 | R29: =G5 -> 0 | S29: =K5 -> 0 | T29: =O5 -> 0 | U29: =S5 -> 0
A30: 3 | B30: =A6 -> 0 | C30: =E6 -> 0 | D30: =I6 -> 0 | E30: =M6 -> 0 | F30: =Q6 -> 0 | G30: =SUM(B30:F30) -> 0 | I30: 3 | J30: =B6 -> 0 | K30: =F6 -> 0 | L30: =J6 -> 0 | M30: =N6 -> 0 | N30: =R6 -> 0 | P30: 3 | Q30: =C6 -> 0 | R30: =G6 -> 0 | S30: =K6 -> 0 | T30: =O6 -> 0 | U30: =S6 -> 0
A31: 4 | B31: =A7 -> 0 | C31: =E7 -> 0 | D31: =I7 -> 0 | E31: =M7 -> 0 | F31: =Q7 -> 0 | G31: =SUM(B31:F31) -> 0 | I31: 4 | J31: =B7 -> 0 | K31: =F7 -> 0 | L31: =J7 -> 0 | M31: =N7 -> 0 | N31: =R7 -> 0 | P31: 4 | Q31: =C7 -> 0 | R31: =G7 -> 0 | S31: =K7 -> 0 | T31: =O7 -> 0 | U31: =S7 -> 0
A32: 5 | B32: =A8 -> 0 | C32: =E8 -> 0 | D32: =I8 -> 0 | E32: =M8 -> 0 | F32: =Q8 -> 0 | G32: =SUM(B32:F32) -> 0 | I32: 5 | J32: =B8 -> 0 | K32: =F8 -> 0 | L32: =J8 -> 0 | M32: =N8 -> 0 | N32: =R8 -> 0 | P32: 5 | Q32: =C8 -> 0 | R32: =G8 -> 0 | S32: =K8 -> 0 | T32: =O8 -> 0 | U32: =S8 -> 0
A33: 6 | B33: =A9 -> 0 | C33: =E9 -> 0 | D33: =I9 -> 0 | E33: =M9 -> 0 | F33: =Q9 -> 0 | G33: =SUM(B33:F33) -> 0 | I33: 6 | J33: =B9 -> 0 | K33: =F9 -> 0 | L33: =J9 -> 0 | M33: =N9 -> 0 | N33: =R9 -> 0 | P33: 6 | Q33: =C9 -> 0 | R33: =G9 -> 0 | S33: =K9 -> 0 | T33: =O9 -> 0 | U33: =S9 -> 0
A34: 7 | B34: =A10 -> 0 | C34: =E10 -> 0 | D34: =I10 -> 0 | E34: =M10 -> 0 | F34: =Q10 -> 0 | G34: =SUM(B34:F34) -> 0 | I34: 7 | J34: =B10 -> 0 | K34: =F10 -> 0 | L34: =J10 -> 0 | M34: =N10 -> 0 | N34: =R10 -> 0 | P34: 7 | Q34: =C10 -> 0 | R34: =G10 -> 0 | S34: =K10 -> 0 | T34: =O10 -> 0 | U34: =S10 -> 0
A35: 8 | B35: =A11 -> 0 | C35: =E11 -> 0 | D35: =I11 -> 0 | E35: =M11 -> 0 | F35: =Q11 -> 0 | G35: =SUM(B35:F35) -> 0 | I35: 8 | J35: =B11 -> 0 | K35: =F11 -> 0 | L35: =J11 -> 0 | M35: =N11 -> 0 | N35: =R11 -> 0 | P35: 8 | Q35: =C11 -> 0 | R35: =G11 -> 0 | S35: =K11 -> 0 | T35: =O11 -> 0 | U35: =S11 -> 0
A36: 9 | B36: =A12 -> 0 | C36: =E12 -> 0 | D36: =I12 -> 0 | E36: =M12 -> 0 | F36: =Q12 -> 0 | G36: =SUM(B36:F36) -> 0 | I36: 9 | J36: =B12 -> 0 | K36: =F12 -> 0 | L36: =J12 -> 0 | M36: =N12 -> 0 | N36: =R12 -> 0 | P36: 9 | Q36: =C12 -> 0 | R36: =G12 -> 0 | S36: =K12 -> 0 | T36: =O12 -> 0 | U36: =S12 -> 0
A37: 10 | B37: =A13 -> 0 | C37: =E13 -> 0 | D37: =I13 -> 0 | E37: =M13 -> 0 | F37: =Q13 -> 0 | G37: =SUM(B37:F37) -> 0 | I37: 10 | J37: =B13 -> 0 | K37: =F13 -> 0 | L37: =J13 -> 0 | M37: =N13 -> 0 | N37: =R13 -> 0 | P37: 10 | Q37: =C13 -> 0 | R37: =G13 -> 0 | S37: =K13 -> 0 | T37: =O13 -> 0 | U37: =S13 -> 0
A38: 11 | B38: =A14 -> 0 | C38: =E14 -> 0 | D38: =I14 -> 0 | E38: =M14 -> 0 | F38: =Q14 -> 0 | G38: =SUM(B38:F38) -> 0 | I38: 11 | J38: =B14 -> 0 | K38: =F14 -> 0 | L38: =J14 -> 0 | M38: =N14 -> 0 | N38: =R14 -> 0 | P38: 11 | Q38: =C14 -> 0 | R38: =G14 -> 0 | S38: =K14 -> 0 | T38: =O14 -> 0 | U38: =S14 -> 0
A39: 12 | B39: =A15 -> 0 | C39: =E15 -> 0 | D39: =I15 -> 0 | E39: =M15 -> 0 | F39: =Q15 -> 0 | G39: =SUM(B39:F39) -> 0 | I39: 12 | J39: =B15 -> 0 | K39: =F15 -> 0 | L39: =J15 -> 0 | M39: =N15 -> 0 | N39: =R15 -> 0 | P39: 12 | Q39: =C15 -> 0 | R39: =G15 -> 0 | S39: =K15 -> 0 | T39: =O15 -> 0 | U39: =S15 -> 0
... A47: 20 | B47: =A23 -> 0 | C47: =E23 -> 0 | D47: =I23 -> 0 | E47: =M23 -> 0 | F47: =Q23 -> 0 | G47: =SUM(B47:F47) -> 0 | I47: 20 | J47: =B23 -> 0 | K47: =F23 -> 0 | L47: =J23 -> 0 | M47: =N23 -> 0 | N47: =R23 -> 0 | P47: 20 | Q47: =C23 -> 0 | R47: =G23 -> 0 | S47: =K23 -> 0 | T47: =O23 -> 0 | U47: =S23 -> 0
A48: totaal | B48: =SUM(B28:B47) -> 0 | C48: =SUM(C28:C47) -> 0 | D48: =SUM(D28:D47) -> 0 | E48: =SUM(E28:E47) -> 0 | F48: =SUM(F28:F47) -> 0 | G48: =SUM(B48:F48) -> 0
A53: Can be modified | B53: test 1 | C53: test 2 | D53: test 3 | E53: test 4 | F53: test 5 | G53: totaal
A54: 1 | B54: =IF(J28=0,0,1) -> 0 | C54: =IF(K28=0,0,1) -> 0 | D54: =IF(L28=0,0,1) -> 0 | E54: =IF(M28=0,0,1) -> 0 | F54: =IF(N28=0,0,1) -> 0 | G54: =SUM(B54:F54) -> 0
A55: 2 | B55: =IF(J29=0,0,1) -> 0 | C55: =IF(K29=0,0,1) -> 0 | D55: =IF(L29=0,0,1) -> 0 | E55: =IF(M29=0,0,1) -> 0 | F55: =IF(N29=0,0,1) -> 0 | G55: =SUM(B55:F55) -> 0
A56: 3 | B56: =IF(J30=0,0,1) -> 0 | C56: =IF(K30=0,0,1) -> 0 | D56: =IF(L30=0,0,1) -> 0 | E56: =IF(M30=0,0,1) -> 0 | F56: =IF(N30=0,0,1) -> 0 | G56: =SUM(B56:F56) -> 0
A57: 4 | B57: =IF(J31=0,0,1) -> 0 | C57: =IF(K31=0,0,1) -> 0 | D57: =IF(L31=0,0,1) -> 0 | E57: =IF(M31=0,0,1) -> 0 | F57: =IF(N31=0,0,1) -> 0 | G57: =SUM(B57:F57) -> 0
A58: 5 | B58: =IF(J32=0,0,1) -> 0 | C58: =IF(K32=0,0,1) -> 0 | D58: =IF(L32=0,0,1) -> 0 | E58: =IF(M32=0,0,1) -> 0 | F58: =IF(N32=0,0,1) -> 0 | G58: =SUM(B58:F58) -> 0
A59: 6 | B59: =IF(J33=0,0,1) -> 0 | C59: =IF(K33=0,0,1) -> 0 | D59: =IF(L33=0,0,1) -> 0 | E59: =IF(M33=0,0,1) -> 0 | F59: =IF(N33=0,0,1) -> 0 | G59: =SUM(B59:F59) -> 0
A60: 7 | B60: =IF(J34=0,0,1) -> 0 | C60: =IF(K34=0,0,1) -> 0 | D60: =IF(L34=0,0,1) -> 0 | E60: =IF(M34=0,0,1) -> 0 | F60: =IF(N34=0,0,1) -> 0 | G60: =SUM(B60:F60) -> 0
A61: 8 | B61: =IF(J35=0,0,1) -> 0 | C61: =IF(K35=0,0,1) -> 0 | D61: =IF(L35=0,0,1) -> 0 | E61: =IF(M35=0,0,1) -> 0 | F61: =IF(N35=0,0,1) -> 0 | G61: =SUM(B61:F61) -> 0
A62: 9 | B62: =IF(J36=0,0,1) -> 0 | C62: =IF(K36=0,0,1) -> 0 | D62: =IF(L36=0,0,1) -> 0 | E62: =IF(M36=0,0,1) -> 0 | F62: =IF(N36=0,0,1) -> 0 | G62: =SUM(B62:F62) -> 0
...

Sheet Impact
C9: Impact | D9: MITM started | E9: can be modified
C10: HTTPS | D10: =HTTPS!G48 & "%" -> 100% | E10: =HTTPS!G74 & "%" -> 0%
C11: Static ARP Entrys | D11: ='Static ARP entrys'!G48 & "%" -> 0% | E11: ='Static ARP entrys'!G74 & "%" -> 0%
C12: VLANs | D12: =VLANs!G48 & "%" -> 0% | E12: =VLANs!G74 & "%" -> 0%
